/home/data/nbc/misc-projects/Salo_PowerReplication/code/conda_env/lib/python3.7/site-packages/nilearn/datasets/__init__.py:96: FutureWarning: Fetchers from the nilearn.datasets module will be updated in version 0.9 to return python strings instead of bytes and Pandas dataframes instead of Numpy arrays.
  "Numpy arrays.", FutureWarning)
Traceback (most recent call last):
  File "/home/data/nbc/misc-projects/Salo_PowerReplication/code/conda_env/lib/python3.7/site-packages/pandas/core/indexes/base.py", line 3361, in get_loc
    return self._engine.get_loc(casted_key)
  File "pandas/_libs/index.pyx", line 76, in pandas._libs.index.IndexEngine.get_loc
  File "pandas/_libs/index.pyx", line 108, in pandas._libs.index.IndexEngine.get_loc
  File "pandas/_libs/hashtable_class_helper.pxi", line 5198, in pandas._libs.hashtable.PyObjectHashTable.get_item
  File "pandas/_libs/hashtable_class_helper.pxi", line 5206, in pandas._libs.hashtable.PyObjectHashTable.get_item
KeyError: 'exclude'

The above exception was the direct cause of the following exception:

Traceback (most recent call last):
  File "/home/data/nbc/misc-projects/Salo_PowerReplication/code/experiment-2/02_gm_correlations_across_masks.py", line 239, in <module>
    dseg_pattern,
  File "/home/data/nbc/misc-projects/Salo_PowerReplication/code/experiment-2/02_gm_correlations_across_masks.py", line 50, in correlate_cort_with_gm
    participants_df = participants_df.loc[participants_df["exclude"] != 1]
  File "/home/data/nbc/misc-projects/Salo_PowerReplication/code/conda_env/lib/python3.7/site-packages/pandas/core/frame.py", line 3455, in __getitem__
    indexer = self.columns.get_loc(key)
  File "/home/data/nbc/misc-projects/Salo_PowerReplication/code/conda_env/lib/python3.7/site-packages/pandas/core/indexes/base.py", line 3363, in get_loc
    raise KeyError(key) from err
KeyError: 'exclude'
/home/data/nbc/misc-projects/Salo_PowerReplication/code/conda_env/lib/python3.7/site-packages/nilearn/datasets/__init__.py:96: FutureWarning: Fetchers from the nilearn.datasets module will be updated in version 0.9 to return python strings instead of bytes and Pandas dataframes instead of Numpy arrays.
  "Numpy arrays.", FutureWarning)
Traceback (most recent call last):
  File "/home/data/nbc/misc-projects/Salo_PowerReplication/code/conda_env/lib/python3.7/site-packages/pandas/core/indexes/base.py", line 3361, in get_loc
    return self._engine.get_loc(casted_key)
  File "pandas/_libs/index.pyx", line 76, in pandas._libs.index.IndexEngine.get_loc
  File "pandas/_libs/index.pyx", line 108, in pandas._libs.index.IndexEngine.get_loc
  File "pandas/_libs/hashtable_class_helper.pxi", line 5198, in pandas._libs.hashtable.PyObjectHashTable.get_item
  File "pandas/_libs/hashtable_class_helper.pxi", line 5206, in pandas._libs.hashtable.PyObjectHashTable.get_item
KeyError: 'exclude'

The above exception was the direct cause of the following exception:

Traceback (most recent call last):
  File "/home/data/nbc/misc-projects/Salo_PowerReplication/code/experiment-2/03_gm_correlations_after_denoising.py", line 233, in <module>
    mask_pattern,
  File "/home/data/nbc/misc-projects/Salo_PowerReplication/code/experiment-2/03_gm_correlations_after_denoising.py", line 44, in correlate_medn_with_oc
    participants_df = participants_df.loc[participants_df["exclude"] != 1]
  File "/home/data/nbc/misc-projects/Salo_PowerReplication/code/conda_env/lib/python3.7/site-packages/pandas/core/frame.py", line 3455, in __getitem__
    indexer = self.columns.get_loc(key)
  File "/home/data/nbc/misc-projects/Salo_PowerReplication/code/conda_env/lib/python3.7/site-packages/pandas/core/indexes/base.py", line 3363, in get_loc
    raise KeyError(key) from err
KeyError: 'exclude'
/home/data/nbc/misc-projects/Salo_PowerReplication/code/conda_env/lib/python3.7/site-packages/nilearn/datasets/__init__.py:96: FutureWarning: Fetchers from the nilearn.datasets module will be updated in version 0.9 to return python strings instead of bytes and Pandas dataframes instead of Numpy arrays.
  "Numpy arrays.", FutureWarning)
Traceback (most recent call last):
  File "/home/data/nbc/misc-projects/Salo_PowerReplication/code/experiment-2/04_methods_for_brain_signals.py", line 29, in <module>
    from utils import plot_confounds  # noqa: E402
ImportError: cannot import name 'plot_confounds' from 'utils' (../utils.py)
/home/data/nbc/misc-projects/Salo_PowerReplication/code/conda_env/lib/python3.7/site-packages/nilearn/datasets/__init__.py:96: FutureWarning: Fetchers from the nilearn.datasets module will be updated in version 0.9 to return python strings instead of bytes and Pandas dataframes instead of Numpy arrays.
  "Numpy arrays.", FutureWarning)
Traceback (most recent call last):
  File "/home/data/nbc/misc-projects/Salo_PowerReplication/code/conda_env/lib/python3.7/site-packages/pandas/core/indexes/base.py", line 3361, in get_loc
    return self._engine.get_loc(casted_key)
  File "pandas/_libs/index.pyx", line 76, in pandas._libs.index.IndexEngine.get_loc
  File "pandas/_libs/index.pyx", line 108, in pandas._libs.index.IndexEngine.get_loc
  File "pandas/_libs/hashtable_class_helper.pxi", line 5198, in pandas._libs.hashtable.PyObjectHashTable.get_item
  File "pandas/_libs/hashtable_class_helper.pxi", line 5206, in pandas._libs.hashtable.PyObjectHashTable.get_item
KeyError: 'dset'

The above exception was the direct cause of the following exception:

Traceback (most recent call last):
  File "/home/data/nbc/misc-projects/Salo_PowerReplication/code/experiment-2/05_ddmra.py", line 113, in <module>
    run_ddmra_analyses(project_dir, participants_file, target_file_patterns, confounds_pattern)
  File "/home/data/nbc/misc-projects/Salo_PowerReplication/code/experiment-2/05_ddmra.py", line 56, in run_ddmra_analyses
    dset_prefix = get_prefixes_mni()[row["dset"]]
  File "/home/data/nbc/misc-projects/Salo_PowerReplication/code/conda_env/lib/python3.7/site-packages/pandas/core/series.py", line 942, in __getitem__
    return self._get_value(key)
  File "/home/data/nbc/misc-projects/Salo_PowerReplication/code/conda_env/lib/python3.7/site-packages/pandas/core/series.py", line 1051, in _get_value
    loc = self.index.get_loc(label)
  File "/home/data/nbc/misc-projects/Salo_PowerReplication/code/conda_env/lib/python3.7/site-packages/pandas/core/indexes/base.py", line 3363, in get_loc
    raise KeyError(key) from err
KeyError: 'dset'
